Workbook
Name SESSION_ID: SESSIONS!$B:$B
Name PARAMETRE_ID_FORMS_DESINSCRIPTION: PARAMETRES!$C$23
Name INSCRIPTION_HEURE_FIN: INSCRIPTIONS!$K:$K
Name DESINSCRIPTION_SESSION: 'DESINSCRIPTION FORM'!$G:$G
Name FORMATION_SUPPORT_LINK: FORMATIONS!$J:$J
Name PARAMETRE_CONNEXION_1: PARAMETRES!$C$30
Name PARAMETRE_ID_MODELE_CONVOC: PARAMETRES!$C$13
Name VALIDATION: VALIDATION!$1:$1
Name PARAMETRE_ID_DOSSIER_CONVOC: PARAMETRES!$C$15
Name PARAMETRE_TEXTE_AGENDA: PARAMETRES!$C$31
Name INSCRIPTION_SESSION_ID: INSCRIPTIONS!$B:$B
Name PARAMETRES_URL_SITE_INSCRIPTION: PARAMETRES!$C$19
Name PARAMETRE_EMAIL: PARAMETRES!$C$10
Name PARAMETRE_URL_SITE: PARAMETRES!$C$19
Name INSCRIPTION_HEURE_DEBUT: INSCRIPTIONS!$J:$J
Name PARAMETRE_NOM_CLIENT: PARAMETRES!$C$8
Name INSCRIPTION_SESSION_DATE: INSCRIPTIONS!$I:$I
Name INSCRIPTION_TITRE_FORMATION: INSCRIPTIONS!$H:$H
Name INSCRIPTION_INSCRIT: INSCRIPTIONS!$C:$F
Name DESINSCRIPTION_EMAIL: 'DESINSCRIPTION FORM'!$C:$C
Name PARAMETRE_ID_FORMS_INSCRIPTION: PARAMETRES!$C$21
Name DESINSCRIPTION_HORODATEUR: 'DESINSCRIPTION FORM'!$B:$B
Name SESSION_FORMATION: SESSIONS!$N:$N
Name FORMATION_FORM_POSITIONNEMENT: FORMATIONS!$K:$K
Name PARAMETRE_ID_SITE: PARAMETRES!$C$17
Name FORMATION_ID: FORMATIONS!$B:$B
Name DESINSCRIPTION_EMAIL_SESSION: 'DESINSCRIPTION FORM'!$A:$A
Name INSCRIPTION_DATE_BRUTE: INSCRIPTIONS!$I:$I
Name PARAMETRE_ID_AGENDA: PARAMETRES!$C$25
Name PARAMETRE_LOGO_CLIENT: PARAMETRES!$B$3
Name INSCRIPTION_SESSION_DUREE: INSCRIPTIONS!$L:$L
Name PARAMATRE_ID_TLA: PARAMETRES!$C$27

Sheet PARAMETRES
C1: NUM IEL - V 20201226 - propulsé par
C3: LEROY MERLIN Inscription En Ligne
B7: Informations générales
B8: Nom du Client / entreprise > | C8: LEROY MERLIN
B10: Mail de contact formation général > | C10: formation@numericoach.fr
B12: Références Externes
B13: ID du docs Modéle de convocation > | C13: 1bJfgjsants-waATPS9Ks5C9ctPG6cu0BKopr5Ek0Gw0 | D13: =IF(C13<>"",HYPERLINK("https://docs.google.com/document/d/"&C13,"Ouvrir le document"),) -> Ouvrir le document
B15: ID du dossier recueillant les convocations > | D15: =IF(C15<>"",HYPERLINK("https://drive.google.com/drive/folders/"&C15,"Ouvrir le dossier"),)
B17: ID site internet > | C17: 1pIokYU-pxb9hRz58Mw0DOMTgHRDlU8yT
B19: URL site inscription > | C19: https://sites.google.com/numericoach.fr/testleroymerlin/accueil
B21: ID Forms Inscription > | C21: 1FAIpQLSeizAy3PO3esDiiugp_bv1E3tocJkuTTplHXzL7ZV9Z6RnVzQ
B23: ID Forms Désinscription > | C23: 1FAIpQLScUsD8xIa_FlYSVu5MCaiAHovywccsOzvwhdKqeTUll50-_nA
B25: ID Agenda >
B27: ID TLA (service Présence / Absences) > | D27: =IFERROR(__xludf.DUMMYFUNCTION("IMPORTRANGE(C27,""VALIDATION"")"),"#N/A") -> #N/A
B29: textes
B30: Lien connexion unique | C30: Connectez-vous le jour J, 5 minutes avant le début du webinaire sur ce lien Meet : https://meet.google.com/apv-qoem-zpc
B31: Texte pour tous les événements

Sheet TABLEAU DE BORD
K1: NUM IEL - V 2020108 - propulsé par
B3: =PARAMETRE_LOGO_CLIENT | C3: LEROY MERLIN Inscription En Ligne | D3: =HYPERLINK(PARAMETRE_URL_SITE,"LIEN VERS LE SITE 🔗") -> LIEN VERS LE SITE 🔗
B7: Suivi des inscriptions : | K7: Répartition des inscriptions par formation
B8: DATE | C8: FORMATION | D8: HEURE DEBUT | E8: HEURE FIN | F8: NB DE PLACES | G8: Nb Inscrits | H8: PLACES RESTANTES
B9: 46224 | C9: Gmail Agenda Meet [FOR-001] | D9: 0.45833333 | E9: 0.5 | F9: 155 | G9: 0 | H9: 155
B10: 46226 | C10: Gemini [FOR-002] | D10: 0.375 | E10: 0.47916667 | F10: 150 | G10: 0 | H10: 150
D11: 0.58333333 | E11: 0.64583333 | F11: 150 | G11: 0 | H11: 150

Sheet SESSIONS
A1: N | B1: {=IF(C:C<>"",IF(C:C=C1,"ID SESSION","SES-"&text(A:A,"0000")),)} -> ID SESSION | C1: FORMATION | D1: DATE | E1: HEURE DEBUT | F1: HEURE FIN | G1: {=IF(B:B<>"",IF(B:B=B1,"DUREE",TEXT(F:F-E:E,"H:MM")),)} -> DUREE | H1: NB DE PLACES | I1: LIEU | J1: INFORMATION COMPLEMENTAIRE | K1: Publier | L1: Nb Inscrits | M1: {=IF(B:B<>"",IF(B:B=B1,"PLACES RESTANTES",H:H-L:L),)} -> PLACES RESTANTES | N1: =IFERROR(__xludf.DUMMYFUNCTION("ArrayFormula(IF(C:C<>"""",IF(C:C=C1,""MODULE ID"",IFNA(REGEXREPLACE(REGEXEXTRACT(C:C,""\[.*\]""),""\[|\]"",""""))),))"),"MODULE ID") -> MODULE ID | O1: {=IF(N:N<>"",IF(N:N=N1,"MODULE TITRE",IFNA(VLOOKUP(N:N,FORMATIONS!B:C,2,),"")),)} -> MODULE TITRE | P1: {=IF(N:N<>"",IF(N:N=N1,"MODULE COMPETENCES",IFNA(VLOOKUP(N:N,FORMATIONS!B:G,6,),"")),)} -> MODULE COMPETENCES | Q1: {=IF(N:N<>"",IF(N:N=N1,"Appli",IFNA(VLOOKUP(N:N,FORMATIONS!B:D,3,),"")),)} -> Appli | R1: {=IF(N:N<>"",IF(N:N=N1,"APPLI URL IMAGE",IFNA(VLOOKUP(N:N,FORMATIONS!B:F,5,),"")),)} -> APPLI URL IMAGE | S1: {=IF(N:N<>"",IF(N:N=N1,"APLI COULEUR",IFNA(VLOOKUP(Q:Q, 'IMPORT APPLIS'!A:C,3,),"")),)} -> APLI COULEUR | T1: {=IF(B:B<>"",IF(B:B=B1,"LIEN INSCRIPTION","https://docs.google.com/forms/d/e/"&PARAMETRE_ID_FORMS_INSCRIPTION&"/viewform?usp=pp_url&entry.1709222927="&O:O&" "&TEXT(D:D,"dddd dd mmmm yyyy")&" ["&B:B&"]"),)} -> LIEN INSCRIPTION | U1: {=IF(N:N<>"",IF(N:N=N1,"MODULE COMPETENCES",IFNA(VLOOKUP(N:N,FORMATIONS!B:E,4,),"")),)} -> MODULE COMPETENCES | X1: =IFERROR(__xludf.DUMMYFUNCTION("ArrayFormula(IF(I:I<>"""",IF(I:I=I1,""LIEU NOM"",IFNA(VLOOKUP(regexreplace(REGEXEXTRACT(I:I,""\[.*\]""),""\[|\]"",""""),LIEUX!B:C,2,))),))"),"LIEU NOM") -> LIEU NOM | Y1: {=IF(B:B<>"",IF(B:B=B1,"LIEN DESINSCRIPTION",HYPERLINK("https://docs.google.com/forms/d/e/1FAIpQLSdmeQMPzCl85UWSmWM6LueOMRFYiRJX2kBSe_mxX7hCk60fPA/viewform?usp=pp_url&entry.2116080188="&O:O&" "&TEXT(D:D,"dddd dd mmmm yyyy")&" ["&B:B&"]")),)} -> LIEN DESINSCRIPTION
A2: 1 | B2: SES-0001 | C2: Gmail Agenda Meet [FOR-001] | D2: 46224 | E2: 0.45833333 | F2: 0.5 | G2: 1:00 | H2: 155 | I2: DISTANCIEL [LIEU-001] | K2: TRUE | L2: =IF(B2<>"",IFNA(COUNTIF(INSCRIPTIONS!B:B,"="&B2),"") - IFNA(COUNTIF('DESINSCRIPTION FORM'!G:G, "="&B2),""),) -> 0 | M2: 155 | N2: =IFERROR(__xludf.DUMMYFUNCTION("""COMPUTED_VALUE"""),"FOR-001") -> FOR-001 | O2: Gmail Agenda Meet | Q2: Agenda Gmail Meet | R2: https://thierryvanoffe.com/numiel/CalendarGmailMeet.png | S2: ea4335 | T2: https://docs.google.com/forms/d/e/1FAIpQLSeizAy3PO3esDiiugp_bv1E3tocJkuTTplHXzL7ZV9Z6RnVzQ/viewform?usp=pp_url&entry.1709222927=Gmail Agenda Meet mardi 21 juillet 2026 [SES-0001] | U2: Prise en main des outils de communication: les 15 fonctionnalités indispensables : Gmail, Agenda, Meet | X2: =IFERROR(__xludf.DUMMYFUNCTION("""COMPUTED_VALUE"""),"DISTANCIEL") -> DISTANCIEL | Y2: https://docs.google.com/forms/d/e/1FAIpQLSdmeQMPzCl85UWSmWM6LueOMRFYiRJX2kBSe_mxX7hCk60fPA/viewform?usp=pp_url&entry.2116080188=Gmail Agenda Meet mardi 21 juillet 2026 [SES-0001]
A3: 2 | B3: SES-0002 | C3: Gemini [FOR-002] | D3: 46226 | E3: 0.375 | F3: 0.47916667 | G3: 2:30 | H3: 150 | I3: DISTANCIEL [LIEU-001] | J3: Formation Gemini avec pratique | K3: TRUE | L3: =IF(B3<>"",IFNA(COUNTIF(INSCRIPTIONS!B:B,"="&B3),"") - IFNA(COUNTIF('DESINSCRIPTION FORM'!G:G, "="&B3),""),) -> 0 | M3: 150 | N3: =IFERROR(__xludf.DUMMYFUNCTION("""COMPUTED_VALUE"""),"FOR-002") -> FOR-002 | O3: Gemini | Q3: GEMINI | T3: https://docs.google.com/forms/d/e/1FAIpQLSeizAy3PO3esDiiugp_bv1E3tocJkuTTplHXzL7ZV9Z6RnVzQ/viewform?usp=pp_url&entry.1709222927=Gemini jeudi 23 juillet 2026 [SES-0002] | U3: Prise en main des outils de Gemini pour savoir l'utilisé de la meilleure façon et d'optimisé c'est taches. | X3: =IFERROR(__xludf.DUMMYFUNCTION("""COMPUTED_VALUE"""),"DISTANCIEL") -> DISTANCIEL | Y3: https://docs.google.com/forms/d/e/1FAIpQLSdmeQMPzCl85UWSmWM6LueOMRFYiRJX2kBSe_mxX7hCk60fPA/viewform?usp=pp_url&entry.2116080188=Gemini jeudi 23 juillet 2026 [SES-0002]
A4: 3 | B4: SES-0003 | C4: Gemini [FOR-002] | D4: 46226 | E4: 0.58333333 | F4: 0.64583333 | G4: 1:30 | H4: 150 | I4: DISTANCIEL [LIEU-001] | J4: Formation Gemini sans pratique | K4: TRUE | L4: =IF(B4<>"",IFNA(COUNTIF(INSCRIPTIONS!B:B,"="&B4),"") - IFNA(COUNTIF('DESINSCRIPTION FORM'!G:G, "="&B4),""),) -> 0 | M4: 150 | N4: =IFERROR(__xludf.DUMMYFUNCTION("""COMPUTED_VALUE"""),"FOR-002") -> FOR-002 | O4: Gemini | Q4: GEMINI | T4: https://docs.google.com/forms/d/e/1FAIpQLSeizAy3PO3esDiiugp_bv1E3tocJkuTTplHXzL7ZV9Z6RnVzQ/viewform?usp=pp_url&entry.1709222927=Gemini jeudi 23 juillet 2026 [SES-0003] | U4: Prise en main des outils de Gemini pour savoir l'utilisé de la meilleure façon et d'optimisé c'est taches. | X4: =IFERROR(__xludf.DUMMYFUNCTION("""COMPUTED_VALUE"""),"DISTANCIEL") -> DISTANCIEL | Y4: https://docs.google.com/forms/d/e/1FAIpQLSdmeQMPzCl85UWSmWM6LueOMRFYiRJX2kBSe_mxX7hCk60fPA/viewform?usp=pp_url&entry.2116080188=Gemini jeudi 23 juillet 2026 [SES-0003]
A5: 4 | K5: FALSE | L5: =IF(B5<>"",IFNA(COUNTIF(INSCRIPTIONS!B:B,"="&B5),"") - IFNA(COUNTIF('DESINSCRIPTION FORM'!G:G, "="&B5),""),)
A6: 5 | K6: FALSE | L6: =IF(B6<>"",IFNA(COUNTIF(INSCRIPTIONS!B:B,"="&B6),"") - IFNA(COUNTIF('DESINSCRIPTION FORM'!G:G, "="&B6),""),)
A7: 6 | K7: FALSE | L7: =IF(B7<>"",IFNA(COUNTIF(INSCRIPTIONS!B:B,"="&B7),"") - IFNA(COUNTIF('DESINSCRIPTION FORM'!G:G, "="&B7),""),)
A8: 7 | K8: FALSE | L8: =IF(B8<>"",IFNA(COUNTIF(INSCRIPTIONS!B:B,"="&B8),"") - IFNA(COUNTIF('DESINSCRIPTION FORM'!G:G, "="&B8),""),)
A9: 8 | K9: FALSE | L9: =IF(B9<>"",IFNA(COUNTIF(INSCRIPTIONS!B:B,"="&B9),"") - IFNA(COUNTIF('DESINSCRIPTION FORM'!G:G, "="&B9),""),)
A10: 9 | K10: FALSE | L10: =IF(B10<>"",IFNA(COUNTIF(INSCRIPTIONS!B:B,"="&B10),"") - IFNA(COUNTIF('DESINSCRIPTION FORM'!G:G, "="&B10),""),)
A11: 10 | K11: FALSE | L11: =IF(B11<>"",IFNA(COUNTIF(INSCRIPTIONS!B:B,"="&B11),"") - IFNA(COUNTIF('DESINSCRIPTION FORM'!G:G, "="&B11),""),)
A12: 11 | K12: FALSE | L12: =IF(B12<>"",IFNA(COUNTIF(INSCRIPTIONS!B:B,"="&B12),"") - IFNA(COUNTIF('DESINSCRIPTION FORM'!G:G, "="&B12),""),)
A13: 12 | K13: FALSE | L13: =IF(B13<>"",IFNA(COUNTIF(INSCRIPTIONS!B:B,"="&B13),"") - IFNA(COUNTIF('DESINSCRIPTION FORM'!G:G, "="&B13),""),)
A14: 14 | K14: FALSE | L14: =IF(B14<>"",IFNA(COUNTIF(INSCRIPTIONS!B:B,"="&B14),"") - IFNA(COUNTIF('DESINSCRIPTION FORM'!G:G, "="&B14),""),)
A15: 15 | K15: FALSE | L15: =IF(B15<>"",IFNA(COUNTIF(INSCRIPTIONS!B:B,"="&B15),"") - IFNA(COUNTIF('DESINSCRIPTION FORM'!G:G, "="&B15),""),)
A16: 16 | K16: FALSE | L16: =IF(B16<>"",IFNA(COUNTIF(INSCRIPTIONS!B:B,"="&B16),"") - IFNA(COUNTIF('DESINSCRIPTION FORM'!G:G, "="&B16),""),)
... A99: 99 | K99: FALSE | L99: =IF(B99<>"",IFNA(COUNTIF(INSCRIPTIONS!B:B,"="&B99),"") - IFNA(COUNTIF('DESINSCRIPTION FORM'!G:G, "="&B99),""),)
K100: FALSE | L100: =IF(B100<>"",IFNA(COUNTIF(INSCRIPTIONS!B:B,"="&B100),"") - IFNA(COUNTIF('DESINSCRIPTION FORM'!G:G, "="&B100),""),)

Sheet FORMATIONS
A1: N | B1: {=IF(C:C<>"",If(C:C=C1,"ID FORMATION","FOR-"&TEXT(A:A,"000")),)} -> ID FORMATION | C1: TITRE DE LA FORMATION | D1: APPLI | E1: DESCRIPTION | F1: {=IF(D:D<>"",IF(D:D=D1,"URL IMG APPLI",IFNA( VLOOKUP(D:D,'IMPORT APPLIS'!A:B,2,FALSE),"")),)} -> URL IMG APPLI | H1: {=IF(C:C<>"",C:C&" ["&B:B&"]",)} -> TITRE DE LA FORMATION [ID FORMATION] | I1: {=IF(F:F<>"",IF(F:F=F1,"IMAGE",IMAGE(F:F)),)} -> IMAGE | J1: Support | K1: formulaire de positionnement
A2: 1 | B2: FOR-001 | C2: Gmail Agenda Meet | D2: Agenda Gmail Meet | E2: Prise en main des outils de communication: les 15 fonctionnalités indispensables : Gmail, Agenda, Meet | F2: https://thierryvanoffe.com/numiel/CalendarGmailMeet.png | H2: Gmail Agenda Meet [FOR-001]
A3: 2 | B3: FOR-002 | C3: Gemini | D3: GEMINI | E3: Prise en main des outils de Gemini pour savoir l'utilisé de la meilleure façon et d'optimisé c'est taches. | H3: Gemini [FOR-002]
A4: 3
A5: 4
A6: 5
A7: 6
A8: 7
A9: 8
A10: 9
A11: 10
A12: 11
A13: 12
A14: 13
A15: 14
... A33: 32

Sheet SESSIONS DANS 3 JOURS
A1: =IFERROR(__xludf.DUMMYFUNCTION("QUERY(SESSIONS!B:O,""SELECT B,O,D,E,F,H,L,M WHERE D = DATE '""&TEXT((TODAY()+3),""YYYY-MM-dd"")&""' AND L <= 7 "")"),"ID SESSION") -> ID SESSION | B1: =IFERROR(__xludf.DUMMYFUNCTION("""COMPUTED_VALUE"""),"MODULE TITRE") -> MODULE TITRE | C1: =IFERROR(__xludf.DUMMYFUNCTION("""COMPUTED_VALUE"""),"DATE") -> DATE | D1: =IFERROR(__xludf.DUMMYFUNCTION("""COMPUTED_VALUE"""),"HEURE DEBUT") -> HEURE DEBUT | E1: =IFERROR(__xludf.DUMMYFUNCTION("""COMPUTED_VALUE"""),"HEURE FIN") -> HEURE FIN | F1: =IFERROR(__xludf.DUMMYFUNCTION("""COMPUTED_VALUE"""),"NB DE PLACES") -> NB DE PLACES | G1: =IFERROR(__xludf.DUMMYFUNCTION("""COMPUTED_VALUE"""),"Nb Inscrits") -> Nb Inscrits | H1: =IFERROR(__xludf.DUMMYFUNCTION("""COMPUTED_VALUE"""),"PLACES RESTANTES") -> PLACES RESTANTES | I1: Inscrits
I2: =IFERROR(__xludf.DUMMYFUNCTION("IF(A2<>"""",IFNA(JOIN(""<br>"",FiLTER('INCRIPTIONS FORMS'!B:B,'INCRIPTIONS FORMS'!K:K=A2))),)"),"")

Sheet INSCRIPTIONSS
A1: Horodateur | B1: Civilite | C1: Prenom | D1: Nom | E1: Votre Entite | F1: Inscription a la formation suivante | G1: Reglement interieur Numericoach | H1: Unite metier (facultatif) | I1: Centre / Site (facultatif) | J1: Adresse e-mail

Sheet INSCRIPTIONS
A1: Horodateur | B1: ID SESSION | C1: EMAIL | D1: {=IF(A:A<>"",IF(A:A=A1,"CIVILITE",IFNA(VLOOKUP(A:A,INSCRIPTIONSS!A:C,3,),"")),)} -> CIVILITE | E1: {=IF(A:A<>"",IF(A:A=A1,"PRENOM",IFNA(VLOOKUP(A:A,INSCRIPTIONSS!A:D,4,),"")),)} -> PRENOM | F1: {=IF(A:A<>"",IF(A:A=A1,"NOM",IFNA(VLOOKUP(A:A,INSCRIPTIONSS!A:E,5,),"")),)} -> NOM | G1: =IFERROR(__xludf.DUMMYFUNCTION("ArrayFormula(IF(B:B<>"""",IF(B:B=B1,""FORMATION ID"",IFNA(REGEXREPLACE(REGEXEXTRACT(VLOOKUP(B:B,SESSIONS!B:C,2,),""\[.*\]""),""\[|\]"",""""))),))"),"FORMATION ID") -> FORMATION ID | H1: {=IF(G:G<>"",IF(G:G=G1,"TITRE FORMATION",IFNA(VLookup(G:G,FORMATIONS!B:C,2,),"")),)} -> TITRE FORMATION | I1: {=IF(B:B<>"",IF(B:B=B1,"DATE",IFNA(VLOOKUP(B:B,SESSIONS!B:D,3,),"")),)} -> DATE | J1: {=IF(B:B<>"",IF(B:B=B1,"HEURE DEBUT",IFNA(VLOOKUP(B:B,SESSIONS!B:E,4,),"")),)} -> HEURE DEBUT | K1: {=IF(B:B<>"",IF(B:B=B1,"HEURE FIN",IFNA(VLOOKUP(B:B,SESSIONS!B:F,5,),"")),)} -> HEURE FIN | L1: {=IF(B:B<>"",IF(B:B=B1,"DURÉE",IFNA(VLOOKUP(B:B,SESSIONS!B:G,6,),"")),)} -> DURÉE | M1: {=IF(G:G<>"",IF(G:G=G1,"DESCRIPTION FORMATION",IFNA(VLOOKUP(G:G,FORMATIONS!B:E,4,),"")),)} -> DESCRIPTION FORMATION | N1: {=IF(G:G<>"",IF(G:G=G1,"APLI FORMATION",IFNA(VLOOKUP(G:G,FORMATIONS!B:D,3,),"")),)} -> APLI FORMATION | O1: {=IF(G:G<>"",IF(G:G=G1,"COMPETENCES FORMATION",IFNA(VLOOKUP(G:G,FORMATIONS!B:G,6,),"")),)} -> COMPETENCES FORMATION | P1: =IFERROR(__xludf.DUMMYFUNCTION("ArrayFormula(IF(B:B<>"""",IF(B:B=B1,""LIEU ID"",IFNA(REGEXREPLACE(REGEXEXTRACT(VLOOKUP(B:B,SESSIONS!B:I,8,),""\[.*\]""),""\[|\]"",""""))),))"),"LIEU ID") -> LIEU ID | Q1: {=IF(P:P<>"",IF(P:P=P1,"LIEU",IFNA(VLOOKUP(P:P,LIEUX!B:C,2,),"")),)} -> LIEU | R1: {=IF(P:P<>"",IF(P:P=P1,"LIEU INFO COMP",IFNA(VLOOKUP(P:P,LIEUX!B:G,6,),"")),)} -> LIEU INFO COMP | S1: {=IF(P:P<>"",IF(P:P=P1,"LIEU ADRESSE",IFNA(VLOOKUP(P:P,LIEUX!B:D,3,),"")),)} -> LIEU ADRESSE | T1: {=IF(P:P<>"",IF(P:P=P1,"LIEU CP",IFNA(VLOOKUP(P:P,LIEUX!B:E,4,),"")),)} -> LIEU CP | U1: {=IF(P:P<>"",IF(P:P=P1,"LIEU VILLE",IFNA(VLOOKUP(P:P,LIEUX!B:F,5,),"")),)} -> LIEU VILLE | V1: {=IF($C:$C<>"",IF($C:$C=C1,"UM",IFNA(VLOOKUP($C:$C,'INCRIPTIONS FORMS'!$B1:I1334,8,),"")),)} -> UM | W1: {=IF($C:$C<>"",IF($C:$C=C1,"SITE",IFNA(VLOOKUP($C:$C,'INCRIPTIONS FORMS'!$B1:J1334,9,),"")),)} -> SITE | X1: {=IF(A:A<>"",IF(A:A=A1,"DATE DESINSCRIPTION",IFNA(VLOOKUP(C:C&B:B,'DESINSCRIPTION FORM'!A:B,2,),"")),)} -> DATE DESINSCRIPTION

Sheet DETAIL DES INSCRIPTIONS PAR SES
B1: Colonnes
A2: Lignes | B2: Valeurs

Sheet UM CENTRE SITE
A1: Votre adresse mail | B1: Votre prénom | C1: Votre nom | D1: Unité métier | E1: Centre / Site

Sheet INSCRIPTIONS OLD
A1: =IFERROR(__xludf.DUMMYFUNCTION("QuERy('INSCRIPTIONS FORM'!A:AY,""SELECT C,J,K,L,M,B,D,E,F,AY,Z,AD WHERE AH is null AND C != 'SES-1000' "",1)"),"ID Inscription à la formation suivante : ") -> ID Inscription à la formation suivante : | B1: =IFERROR(__xludf.DUMMYFUNCTION("""COMPUTED_VALUE"""),"TITRE de la formation") -> TITRE de la formation | C1: =IFERROR(__xludf.DUMMYFUNCTION("""COMPUTED_VALUE"""),"Date Session") -> Date Session | D1: =IFERROR(__xludf.DUMMYFUNCTION("""COMPUTED_VALUE"""),"Heure Début") -> Heure Début | E1: =IFERROR(__xludf.DUMMYFUNCTION("""COMPUTED_VALUE"""),"Heure Fin") -> Heure Fin | F1: =IFERROR(__xludf.DUMMYFUNCTION("""COMPUTED_VALUE"""),"Adresse e-mail") -> Adresse e-mail | G1: =IFERROR(__xludf.DUMMYFUNCTION("""COMPUTED_VALUE"""),"Civilité") -> Civilité | H1: =IFERROR(__xludf.DUMMYFUNCTION("""COMPUTED_VALUE"""),"Prénom") -> Prénom | I1: =IFERROR(__xludf.DUMMYFUNCTION("""COMPUTED_VALUE"""),"Nom") -> Nom | J1: =IFERROR(__xludf.DUMMYFUNCTION("""COMPUTED_VALUE"""),"Votre Entité") -> Votre Entité | K1: =IFERROR(__xludf.DUMMYFUNCTION("""COMPUTED_VALUE"""),"PDF CONVOCATION URL") -> PDF CONVOCATION URL | L1: =IFERROR(__xludf.DUMMYFUNCTION("""COMPUTED_VALUE"""),"LIEN DESINSCRIPTION") -> LIEN DESINSCRIPTION | M1: {=IF(K:K<>"",IF(K:K=K1,"PDF CONVOCATION",HYPERLINK(K:K,"PDF CONVOCATION "&CHAR(10)&A:A&" " &G:G&" "&H:H&" "&I:I)),)} -> PDF CONVOCATION | N1: {=IF(K:K<>"",IF(K:K=K1,"DESINSCRIPTION",HYPERLINK(L:L,"DESINSCRIPTION "&CHAR(10)&A:A&" " &G:G&" "&H:H&" "&I:I)),)} -> DESINSCRIPTION | O1: {=IF(A:A<>"",IF(A:A=A1,"DUREE",IFNA(VLOOKUP(A:A,SESSIONS!B:G,6,FALSE),"")),)} -> DUREE | P1: {=IF(A:A<>"",IF(A:A=A1,"PARTICIPATION",IFNA(VLOOKUP(A:A&"-"&F:F,'IMPORT TLA'!A:E,5,FALSE),"")),)} -> PARTICIPATION | Q1: {=IF(A:A<>"",IF(A:A=A1,"DATE BRUTE",ifNA(VLooKup(A:A,SESSIONS!B:D,3,FALSE),"")),)} -> DATE BRUTE

Sheet Inscriptions détaillées par séa
A1: #REF!

Sheet Détail2-Google Slides, Docs, Sh
A1: Adresse e-mail | B1: Civilité | C1: Prénom | D1: Nom | E1: Votre Entité | F1: Inscription à la formation suivante :
A2: antoine.martin@amcms.net | B2: M. | C2: Antoine | D2: MARTIN | F2: Google Slides, Docs, Sheets, Forms mardi 11 mai 2021 [SES-0003]
A3: antoine.martin@amcms.net | B3: M. | C3: Antoine | D3: MARTIN | F3: Google Slides, Docs, Sheets, Forms mardi 11 mai 2021 [SES-0003]
A4: trst@tsst.com | B4: M. | C4: Jean | D4: Bon | F4: Google Slides, Docs, Sheets, Forms mardi 11 mai 2021 [SES-0003]
A5: thierry@numericoach.fr | B5: M. | C5: THIERRY | D5: VANOFFE | F5: Google Slides, Docs, Sheets, Forms mardi 11 mai 2021 [SES-0003]

Sheet GED
A1: TIME | B1: TYPE DOC | C1: SESSION | D1: EMAIL | E1: URL | F1: NAME
A2: 44265.414 | B2: CONVOCATION | C2: SES-0001 | D2: antoine.martin@amcms.net | E2: https://drive.google.com/file/d/1zMZ07vrHqxepk0rVVoD8IQV46RSsfYNt/view?usp=drivesdk | F2: convocation SES-0001 Antoine MARTIN
A3: 44265.512 | B3: CONVOCATION | C3: SES-0002 | D3: antoine.martin@amcms.net | E3: https://drive.google.com/file/d/1dvN9USr_A-jLeDk6BrPj1JqN5TE1_GJY/view?usp=drivesdk | F3: convocation SES-0002 Antoine MARTIN
A4: 44265.519 | B4: CONVOCATION | C4: SES-0003 | D4: antoine.martin@amcms.net | E4: https://drive.google.com/file/d/1278sYVxEa5a7mKCQP3gtUOqK2xkycD85/view?usp=drivesdk | F4: convocation SES-0003 Antoine MARTIN
A5: 44265.52 | B5: CONVOCATION | C5: SES-0001 | D5: Antoine.martin@amcms.net | E5: https://drive.google.com/file/d/1Takmp2jWDsv1zWk1MIcrhqpdE62YNSjb/view?usp=drivesdk | F5: convocation SES-0001 Antoine MARTIN
A6: 44266.009 | B6: CONVOCATION | C6: SES-0001 | D6: thierry@numericoach.fr | E6: https://drive.google.com/file/d/1gAqHpK0EvehjjlHF57Ph3M8CDtuJxmQe/view?usp=drivesdk | F6: convocation SES-0001 THIERRY VANOFFE
A7: 44266.295 | B7: CONVOCATION | C7: SES-0002 | D7: antoine.martin@amcms.net | E7: https://drive.google.com/file/d/1CxzFE1Wbn_sgLzBSBnkdMsHrjg7rOjGn/view?usp=drivesdk | F7: convocation SES-0002 Antoine MARTIN
A8: 44266.296 | B8: CONVOCATION | C8: SES-0003 | D8: antoine.martin@amcms.net | E8: https://drive.google.com/file/d/1YIOW3D3W8ZL1QSHFeIZD6vJYdy5aSglb/view?usp=drivesdk | F8: convocation SES-0003 Antoine MARTIN
A9: 44266.299 | B9: CONVOCATION | C9: SES-0003 | D9: antoine.martin@amcms.ner | E9: https://drive.google.com/file/d/1vt8MKLhgHt0V4Ivh5fwdORT0lm-DaQsT/view?usp=drivesdk | F9: convocation SES-0003 Antoine MARTIN
A10: 44266.302 | B10: CONVOCATION | C10: SES-0003 | D10: antoine.martin@amcms.net | E10: https://drive.google.com/file/d/1nWVKb7t100NgycGki0J9UFu46wNxwtOf/view?usp=drivesdk | F10: convocation SES-0003 Antoine MARTIN
A11: 44266.916 | B11: CONVOCATION | C11: SES-0002 | D11: thierry@numericoach.fr | E11: https://drive.google.com/file/d/1irXIgCmq3UnSp45OWMM9Etq88MPeQua6/view?usp=drivesdk | F11: convocation SES-0002 THIERRY VANOFFE
A12: 44266.918 | B12: CONVOCATION | C12: SES-0003 | D12: trst@tsst.com | E12: https://drive.google.com/file/d/1RmLiraFC_x-9GiCtWSP0vAoYKs4lgwii/view?usp=drivesdk | F12: convocation SES-0003 Jean Bon
A13: 44266.953 | B13: CONVOCATION | C13: SES-0003 | D13: thierry@numericoach.fr | E13: https://drive.google.com/file/d/1X3PX9-STZZwvhMPpui9ixg0pImxiX_dW/view?usp=drivesdk | F13: convocation SES-0003 THIERRY VANOFFE
... A1334: 44543.599 | B1334: CONVOCATION | C1334: SES-0052 | D1334: snobis@ucpa.asso.fr | E1334: https://drive.google.com/file/d/12s3_0uL1uB23ZAgERYO6BkBaCBLQfdEI/view?usp=drivesdk | F1334: convocation SES-0052 Sébastien Nobis

Sheet CONSOLIDATION GED
A1: {=IF(B:B<>"",C:C&"_"&B:B,)} -> EMAIL_SESSION | B1: =IFERROR(__xludf.DUMMYFUNCTION("QUERY(GED!C:E)"),"SESSION") -> SESSION | C1: =IFERROR(__xludf.DUMMYFUNCTION("""COMPUTED_VALUE"""),"EMAIL") -> EMAIL | D1: =IFERROR(__xludf.DUMMYFUNCTION("""COMPUTED_VALUE"""),"URL") -> URL
A2: antoine.martin@amcms.net_SES-0001 | B2: =IFERROR(__xludf.DUMMYFUNCTION("""COMPUTED_VALUE"""),"SES-0001") -> SES-0001 | C2: =IFERROR(__xludf.DUMMYFUNCTION("""COMPUTED_VALUE"""),"antoine.martin@amcms.net") -> antoine.martin@amcms.net | D2: =IFERROR(__xludf.DUMMYFUNCTION("""COMPUTED_VALUE"""),"https://drive.google.com/file/d/1zMZ07vrHqxepk0rVVoD8IQV46RSsfYNt/view?usp=drivesdk") -> https://drive.google.com/file/d/1zMZ07vrHqxepk0rVVoD8IQV46RSsfYNt/view?usp=drivesdk
A3: antoine.martin@amcms.net_SES-0002 | B3: =IFERROR(__xludf.DUMMYFUNCTION("""COMPUTED_VALUE"""),"SES-0002") -> SES-0002 | C3: =IFERROR(__xludf.DUMMYFUNCTION("""COMPUTED_VALUE"""),"antoine.martin@amcms.net") -> antoine.martin@amcms.net | D3: =IFERROR(__xludf.DUMMYFUNCTION("""COMPUTED_VALUE"""),"https://drive.google.com/file/d/1dvN9USr_A-jLeDk6BrPj1JqN5TE1_GJY/view?usp=drivesdk") -> https://drive.google.com/file/d/1dvN9USr_A-jLeDk6BrPj1JqN5TE1_GJY/view?usp=drivesdk
A4: antoine.martin@amcms.net_SES-0003 | B4: =IFERROR(__xludf.DUMMYFUNCTION("""COMPUTED_VALUE"""),"SES-0003") -> SES-0003 | C4: =IFERROR(__xludf.DUMMYFUNCTION("""COMPUTED_VALUE"""),"antoine.martin@amcms.net") -> antoine.martin@amcms.net | D4: =IFERROR(__xludf.DUMMYFUNCTION("""COMPUTED_VALUE"""),"https://drive.google.com/file/d/1278sYVxEa5a7mKCQP3gtUOqK2xkycD85/view?usp=drivesdk") -> https://drive.google.com/file/d/1278sYVxEa5a7mKCQP3gtUOqK2xkycD85/view?usp=drivesdk
A5: Antoine.martin@amcms.net_SES-0001 | B5: =IFERROR(__xludf.DUMMYFUNCTION("""COMPUTED_VALUE"""),"SES-0001") -> SES-0001 | C5: =IFERROR(__xludf.DUMMYFUNCTION("""COMPUTED_VALUE"""),"Antoine.martin@amcms.net") -> Antoine.martin@amcms.net | D5: =IFERROR(__xludf.DUMMYFUNCTION("""COMPUTED_VALUE"""),"https://drive.google.com/file/d/1Takmp2jWDsv1zWk1MIcrhqpdE62YNSjb/view?usp=drivesdk") -> https://drive.google.com/file/d/1Takmp2jWDsv1zWk1MIcrhqpdE62YNSjb/view?usp=drivesdk
A6: thierry@numericoach.fr_SES-0001 | B6: =IFERROR(__xludf.DUMMYFUNCTION("""COMPUTED_VALUE"""),"SES-0001") -> SES-0001 | C6: =IFERROR(__xludf.DUMMYFUNCTION("""COMPUTED_VALUE"""),"thierry@numericoach.fr") -> thierry@numericoach.fr | D6: =IFERROR(__xludf.DUMMYFUNCTION("""COMPUTED_VALUE"""),"https://drive.google.com/file/d/1gAqHpK0EvehjjlHF57Ph3M8CDtuJxmQe/view?usp=drivesdk") -> https://drive.google.com/file/d/1gAqHpK0EvehjjlHF57Ph3M8CDtuJxmQe/view?usp=drivesdk
A7: antoine.martin@amcms.net_SES-0002 | B7: =IFERROR(__xludf.DUMMYFUNCTION("""COMPUTED_VALUE"""),"SES-0002") -> SES-0002 | C7: =IFERROR(__xludf.DUMMYFUNCTION("""COMPUTED_VALUE"""),"antoine.martin@amcms.net") -> antoine.martin@amcms.net | D7: =IFERROR(__xludf.DUMMYFUNCTION("""COMPUTED_VALUE"""),"https://drive.google.com/file/d/1CxzFE1Wbn_sgLzBSBnkdMsHrjg7rOjGn/view?usp=drivesdk") -> https://drive.google.com/file/d/1CxzFE1Wbn_sgLzBSBnkdMsHrjg7rOjGn/view?usp=drivesdk
A8: antoine.martin@amcms.net_SES-0003 | B8: =IFERROR(__xludf.DUMMYFUNCTION("""COMPUTED_VALUE"""),"SES-0003") -> SES-0003 | C8: =IFERROR(__xludf.DUMMYFUNCTION("""COMPUTED_VALUE"""),"antoine.martin@amcms.net") -> antoine.martin@amcms.net | D8: =IFERROR(__xludf.DUMMYFUNCTION("""COMPUTED_VALUE"""),"https://drive.google.com/file/d/1YIOW3D3W8ZL1QSHFeIZD6vJYdy5aSglb/view?usp=drivesdk") -> https://drive.google.com/file/d/1YIOW3D3W8ZL1QSHFeIZD6vJYdy5aSglb/view?usp=drivesdk
A9: antoine.martin@amcms.ner_SES-0003 | B9: =IFERROR(__xludf.DUMMYFUNCTION("""COMPUTED_VALUE"""),"SES-0003") -> SES-0003 | C9: =IFERROR(__xludf.DUMMYFUNCTION("""COMPUTED_VALUE"""),"antoine.martin@amcms.ner") -> antoine.martin@amcms.ner | D9: =IFERROR(__xludf.DUMMYFUNCTION("""COMPUTED_VALUE"""),"https://drive.google.com/file/d/1vt8MKLhgHt0V4Ivh5fwdORT0lm-DaQsT/view?usp=drivesdk") -> https://drive.google.com/file/d/1vt8MKLhgHt0V4Ivh5fwdORT0lm-DaQsT/view?usp=drivesdk
A10: antoine.martin@amcms.net_SES-0003 | B10: =IFERROR(__xludf.DUMMYFUNCTION("""COMPUTED_VALUE"""),"SES-0003") -> SES-0003 | C10: =IFERROR(__xludf.DUMMYFUNCTION("""COMPUTED_VALUE"""),"antoine.martin@amcms.net") -> antoine.martin@amcms.net | D10: =IFERROR(__xludf.DUMMYFUNCTION("""COMPUTED_VALUE"""),"https://drive.google.com/file/d/1nWVKb7t100NgycGki0J9UFu46wNxwtOf/view?usp=drivesdk") -> https://drive.google.com/file/d/1nWVKb7t100NgycGki0J9UFu46wNxwtOf/view?usp=drivesdk
A11: thierry@numericoach.fr_SES-0002 | B11: =IFERROR(__xludf.DUMMYFUNCTION("""COMPUTED_VALUE"""),"SES-0002") -> SES-0002 | C11: =IFERROR(__xludf.DUMMYFUNCTION("""COMPUTED_VALUE"""),"thierry@numericoach.fr") -> thierry@numericoach.fr | D11: =IFERROR(__xludf.DUMMYFUNCTION("""COMPUTED_VALUE"""),"https://drive.google.com/file/d/1irXIgCmq3UnSp45OWMM9Etq88MPeQua6/view?usp=drivesdk") -> https://drive.google.com/file/d/1irXIgCmq3UnSp45OWMM9Etq88MPeQua6/view?usp=drivesdk
A12: trst@tsst.com_SES-0003 | B12: =IFERROR(__xludf.DUMMYFUNCTION("""COMPUTED_VALUE"""),"SES-0003") -> SES-0003 | C12: =IFERROR(__xludf.DUMMYFUNCTION("""COMPUTED_VALUE"""),"trst@tsst.com") -> trst@tsst.com | D12: =IFERROR(__xludf.DUMMYFUNCTION("""COMPUTED_VALUE"""),"https://drive.google.com/file/d/1RmLiraFC_x-9GiCtWSP0vAoYKs4lgwii/view?usp=drivesdk") -> https://drive.google.com/file/d/1RmLiraFC_x-9GiCtWSP0vAoYKs4lgwii/view?usp=drivesdk
A13: thierry@numericoach.fr_SES-0003 | B13: =IFERROR(__xludf.DUMMYFUNCTION("""COMPUTED_VALUE"""),"SES-0003") -> SES-0003 | C13: =IFERROR(__xludf.DUMMYFUNCTION("""COMPUTED_VALUE"""),"thierry@numericoach.fr") -> thierry@numericoach.fr | D13: =IFERROR(__xludf.DUMMYFUNCTION("""COMPUTED_VALUE"""),"https://drive.google.com/file/d/1X3PX9-STZZwvhMPpui9ixg0pImxiX_dW/view?usp=drivesdk") -> https://drive.google.com/file/d/1X3PX9-STZZwvhMPpui9ixg0pImxiX_dW/view?usp=drivesdk
A14: sbouteille@ucpa.asso.fr_SES-0001 | B14: =IFERROR(__xludf.DUMMYFUNCTION("""COMPUTED_VALUE"""),"SES-0001") -> SES-0001 | C14: =IFERROR(__xludf.DUMMYFUNCTION("""COMPUTED_VALUE"""),"sbouteille@ucpa.asso.fr") -> sbouteille@ucpa.asso.fr | D14: =IFERROR(__xludf.DUMMYFUNCTION("""COMPUTED_VALUE"""),"https://drive.google.com/file/d/13iW9V8aKH2qijagfAQu5rCdBu6T3IhIQ/view?usp=drivesdk") -> https://drive.google.com/file/d/13iW9V8aKH2qijagfAQu5rCdBu6T3IhIQ/view?usp=drivesdk
A15: pbreton@ucpa.asso.fr_SES-0001 | B15: =IFERROR(__xludf.DUMMYFUNCTION("""COMPUTED_VALUE"""),"SES-0001") -> SES-0001 | C15: =IFERROR(__xludf.DUMMYFUNCTION("""COMPUTED_VALUE"""),"pbreton@ucpa.asso.fr") -> pbreton@ucpa.asso.fr | D15: =IFERROR(__xludf.DUMMYFUNCTION("""COMPUTED_VALUE"""),"https://drive.google.com/file/d/1bmgNaIBveO7fhm1ohE3nT6KwNuVmYaol/view?usp=drivesdk") -> https://drive.google.com/file/d/1bmgNaIBveO7fhm1ohE3nT6KwNuVmYaol/view?usp=drivesdk
A16: ckolodka@ucpa.asso.fr_SES-0001 | B16: =IFERROR(__xludf.DUMMYFUNCTION("""COMPUTED_VALUE"""),"SES-0001") -> SES-0001 | C16: =IFERROR(__xludf.DUMMYFUNCTION("""COMPUTED_VALUE"""),"ckolodka@ucpa.asso.fr") -> ckolodka@ucpa.asso.fr | D16: =IFERROR(__xludf.DUMMYFUNCTION("""COMPUTED_VALUE"""),"https://drive.google.com/file/d/1c9sYOLd2AoaTQTHaw91jjbQ7hND_ffPH/view?usp=drivesdk") -> https://drive.google.com/file/d/1c9sYOLd2AoaTQTHaw91jjbQ7hND_ffPH/view?usp=drivesdk
A17: pbreton@ucpa.asso.fr_SES-0002 | B17: =IFERROR(__xludf.DUMMYFUNCTION("""COMPUTED_VALUE"""),"SES-0002") -> SES-0002 | C17: =IFERROR(__xludf.DUMMYFUNCTION("""COMPUTED_VALUE"""),"pbreton@ucpa.asso.fr") -> pbreton@ucpa.asso.fr | D17: =IFERROR(__xludf.DUMMYFUNCTION("""COMPUTED_VALUE"""),"https://drive.google.com/file/d/1XEST2q3ZUtr-B8qA6o1q8J3gm5J1MJRL/view?usp=drivesdk") -> https://drive.google.com/file/d/1XEST2q3ZUtr-B8qA6o1q8J3gm5J1MJRL/view?usp=drivesdk
A18: emonard@ucpa.asso.fr_SES-0001 | B18: =IFERROR(__xludf.DUMMYFUNCTION("""COMPUTED_VALUE"""),"SES-0001") -> SES-0001 | C18: =IFERROR(__xludf.DUMMYFUNCTION("""COMPUTED_VALUE"""),"emonard@ucpa.asso.fr") -> emonard@ucpa.asso.fr | D18: =IFERROR(__xludf.DUMMYFUNCTION("""COMPUTED_VALUE"""),"https://drive.google.com/file/d/1Y-r3ggNOwYWX1pR8SKsU4XfDZ2aRmAjk/view?usp=drivesdk") -> https://drive.google.com/file/d/1Y-r3ggNOwYWX1pR8SKsU4XfDZ2aRmAjk/view?usp=drivesdk
A19: pdeplaix@ucpa.asso.fr_SES-0001 | B19: =IFERROR(__xludf.DUMMYFUNCTION("""COMPUTED_VALUE"""),"SES-0001") -> SES-0001 | C19: =IFERROR(__xludf.DUMMYFUNCTION("""COMPUTED_VALUE"""),"pdeplaix@ucpa.asso.fr") -> pdeplaix@ucpa.asso.fr | D19: =IFERROR(__xludf.DUMMYFUNCTION("""COMPUTED_VALUE"""),"https://drive.google.com/file/d/12LUy-jcdhnSyPxLky-4JP1YWD_3chyke/view?usp=drivesdk") -> https://drive.google.com/file/d/12LUy-jcdhnSyPxLky-4JP1YWD_3chyke/view?usp=drivesdk
A20: tbrouard@ucpa.asso.fr_SES-0001 | B20: =IFERROR(__xludf.DUMMYFUNCTION("""COMPUTED_VALUE"""),"SES-0001") -> SES-0001 | C20: =IFERROR(__xludf.DUMMYFUNCTION("""COMPUTED_VALUE"""),"tbrouard@ucpa.asso.fr") -> tbrouard@ucpa.asso.fr | D20: =IFERROR(__xludf.DUMMYFUNCTION("""COMPUTED_VALUE"""),"https://drive.google.com/file/d/15w0PoontBUoL0iw3cfyEGBPjbnt8qipR/view?usp=drivesdk") -> https://drive.google.com/file/d/15w0PoontBUoL0iw3cfyEGBPjbnt8qipR/view?usp=drivesdk
A21: ckolodka@ucpa.asso.fr_SES-0002 | B21: =IFERROR(__xludf.DUMMYFUNCTION("""COMPUTED_VALUE"""),"SES-0002") -> SES-0002 | C21: =IFERROR(__xludf.DUMMYFUNCTION("""COMPUTED_VALUE"""),"ckolodka@ucpa.asso.fr") -> ckolodka@ucpa.asso.fr | D21: =IFERROR(__xludf.DUMMYFUNCTION("""COMPUTED_VALUE"""),"https://drive.google.com/file/d/14vNaogpj8ilnXTRcV2Gw6sXu4XjK2Hta/view?usp=drivesdk") -> https://drive.google.com/file/d/14vNaogpj8ilnXTRcV2Gw6sXu4XjK2Hta/view?usp=drivesdk
A22: lmosnier@ucpa.asso.fr_SES-0001 | B22: =IFERROR(__xludf.DUMMYFUNCTION("""COMPUTED_VALUE"""),"SES-0001") -> SES-0001 | C22: =IFERROR(__xludf.DUMMYFUNCTION("""COMPUTED_VALUE"""),"lmosnier@ucpa.asso.fr") -> lmosnier@ucpa.asso.fr | D22: =IFERROR(__xludf.DUMMYFUNCTION("""COMPUTED_VALUE"""),"https://drive.google.com/file/d/1ViLdVQA_-hOe33FFUj2TF_MT17J4ZiVx/view?usp=drivesdk") -> https://drive.google.com/file/d/1ViLdVQA_-hOe33FFUj2TF_MT17J4ZiVx/view?usp=drivesdk
A23: lmosnier@ucpa.asso.fr_SES-0002 | B23: =IFERROR(__xludf.DUMMYFUNCTION("""COMPUTED_VALUE"""),"SES-0002") -> SES-0002 | C23: =IFERROR(__xludf.DUMMYFUNCTION("""COMPUTED_VALUE"""),"lmosnier@ucpa.asso.fr") -> lmosnier@ucpa.asso.fr | D23: =IFERROR(__xludf.DUMMYFUNCTION("""COMPUTED_VALUE"""),"https://drive.google.com/file/d/1y0oVcbXwyavgnH3iVNx1l0ai9_mmjKAx/view?usp=drivesdk") -> https://drive.google.com/file/d/1y0oVcbXwyavgnH3iVNx1l0ai9_mmjKAx/view?usp=drivesdk
A24: pdeplaix@ucpa.asso.fr_SES-0002 | B24: =IFERROR(__xludf.DUMMYFUNCTION("""COMPUTED_VALUE"""),"SES-0002") -> SES-0002 | C24: =IFERROR(__xludf.DUMMYFUNCTION("""COMPUTED_VALUE"""),"pdeplaix@ucpa.asso.fr") -> pdeplaix@ucpa.asso.fr | D24: =IFERROR(__xludf.DUMMYFUNCTION("""COMPUTED_VALUE"""),"https://drive.google.com/file/d/18kGF12W0nZx3JnyEWpyoXXf01F87fUMt/view?usp=drivesdk") -> https://drive.google.com/file/d/18kGF12W0nZx3JnyEWpyoXXf01F87fUMt/view?usp=drivesdk
A25: apouffier@ucpasl.com_SES-0001 | B25: =IFERROR(__xludf.DUMMYFUNCTION("""COMPUTED_VALUE"""),"SES-0001") -> SES-0001 | C25: =IFERROR(__xludf.DUMMYFUNCTION("""COMPUTED_VALUE"""),"apouffier@ucpasl.com") -> apouffier@ucpasl.com | D25: =IFERROR(__xludf.DUMMYFUNCTION("""COMPUTED_VALUE"""),"https://drive.google.com/file/d/1QJ8782dNxX0Bu9nXd2T6hdlXLh6aKeGE/view?usp=drivesdk") -> https://drive.google.com/file/d/1QJ8782dNxX0Bu9nXd2T6hdlXLh6aKeGE/view?usp=drivesdk
A26: apouffier@ucpasl.com_SES-0002 | B26: =IFERROR(__xludf.DUMMYFUNCTION("""COMPUTED_VALUE"""),"SES-0002") -> SES-0002 | C26: =IFERROR(__xludf.DUMMYFUNCTION("""COMPUTED_VALUE"""),"apouffier@ucpasl.com") -> apouffier@ucpasl.com | D26: =IFERROR(__xludf.DUMMYFUNCTION("""COMPUTED_VALUE"""),"https://drive.google.com/file/d/1YsF1R2szHKKe1GAGW_Jw1AM760XoY9_G/view?usp=drivesdk") -> https://drive.google.com/file/d/1YsF1R2szHKKe1GAGW_Jw1AM760XoY9_G/view?usp=drivesdk
A27: nboumahammed@ucpa.asso.fr_SES-0002 | B27: =IFERROR(__xludf.DUMMYFUNCTION("""COMPUTED_VALUE"""),"SES-0002") -> SES-0002 | C27: =IFERROR(__xludf.DUMMYFUNCTION("""COMPUTED_VALUE"""),"nboumahammed@ucpa.asso.fr") -> nboumahammed@ucpa.asso.fr | D27: =IFERROR(__xludf.DUMMYFUNCTION("""COMPUTED_VALUE"""),"https://drive.google.com/file/d/1mbug-T6maELyd90i9jGi4t3Gn3Co91uT/view?usp=drivesdk") -> https://drive.google.com/file/d/1mbug-T6maELyd90i9jGi4t3Gn3Co91uT/view?usp=drivesdk
A28: jgranger@ucpa.asso.fr_SES-0001 | B28: =IFERROR(__xludf.DUMMYFUNCTION("""COMPUTED_VALUE"""),"SES-0001") -> SES-0001 | C28: =IFERROR(__xludf.DUMMYFUNCTION("""COMPUTED_VALUE"""),"jgranger@ucpa.asso.fr") -> jgranger@ucpa.asso.fr | D28: =IFERROR(__xludf.DUMMYFUNCTION("""COMPUTED_VALUE"""),"https://drive.google.com/file/d/1mEzh41oz_2hRCXX7H4WdkXV0nv850e_O/view?usp=drivesdk") -> https://drive.google.com/file/d/1mEzh41oz_2hRCXX7H4WdkXV0nv850e_O/view?usp=drivesdk
A29: lmaury@ucpa.asso.fr_SES-0001 | B29: =IFERROR(__xludf.DUMMYFUNCTION("""COMPUTED_VALUE"""),"SES-0001") -> SES-0001 | C29: =IFERROR(__xludf.DUMMYFUNCTION("""COMPUTED_VALUE"""),"lmaury@ucpa.asso.fr") -> lmaury@ucpa.asso.fr | D29: =IFERROR(__xludf.DUMMYFUNCTION("""COMPUTED_VALUE"""),"https://drive.google.com/file/d/1ZzMFEinZnR7pf8OmsTE2t3CQGAz2ARkP/view?usp=drivesdk") -> https://drive.google.com/file/d/1ZzMFEinZnR7pf8OmsTE2t3CQGAz2ARkP/view?usp=drivesdk
A30: lmaury@ucpa.asso.fr_SES-0002 | B30: =IFERROR(__xludf.DUMMYFUNCTION("""COMPUTED_VALUE"""),"SES-0002") -> SES-0002 | C30: =IFERROR(__xludf.DUMMYFUNCTION("""COMPUTED_VALUE"""),"lmaury@ucpa.asso.fr") -> lmaury@ucpa.asso.fr | D30: =IFERROR(__xludf.DUMMYFUNCTION("""COMPUTED_VALUE"""),"https://drive.google.com/file/d/1avmG1ZuzkOPeALMQvqE_0-IISAPqvitz/view?usp=drivesdk") -> https://drive.google.com/file/d/1avmG1ZuzkOPeALMQvqE_0-IISAPqvitz/view?usp=drivesdk
A31: pvareille@ucpa.asso.fr_SES-0001 | B31: =IFERROR(__xludf.DUMMYFUNCTION("""COMPUTED_VALUE"""),"SES-0001") -> SES-0001 | C31: =IFERROR(__xludf.DUMMYFUNCTION("""COMPUTED_VALUE"""),"pvareille@ucpa.asso.fr") -> pvareille@ucpa.asso.fr | D31: =IFERROR(__xludf.DUMMYFUNCTION("""COMPUTED_VALUE"""),"https://drive.google.com/file/d/1O2X9odFj64VbNxugD3-wUy8cjK3yPDYo/view?usp=drivesdk") -> https://drive.google.com/file/d/1O2X9odFj64VbNxugD3-wUy8cjK3yPDYo/view?usp=drivesdk
A32: pvareille@ucpa.asso.fr_SES-0002 | B32: =IFERROR(__xludf.DUMMYFUNCTION("""COMPUTED_VALUE"""),"SES-0002") -> SES-0002 | C32: =IFERROR(__xludf.DUMMYFUNCTION("""COMPUTED_VALUE"""),"pvareille@ucpa.asso.fr") -> pvareille@ucpa.asso.fr | D32: =IFERROR(__xludf.DUMMYFUNCTION("""COMPUTED_VALUE"""),"https://drive.google.com/file/d/1dw-Ptd50H-9Hc6Mh2DWENxM2x-UmrpGF/view?usp=drivesdk") -> https://drive.google.com/file/d/1dw-Ptd50H-9Hc6Mh2DWENxM2x-UmrpGF/view?usp=drivesdk
A33: aiftene@ucpa.asso.fr_SES-0001 | B33: =IFERROR(__xludf.DUMMYFUNCTION("""COMPUTED_VALUE"""),"SES-0001") -> SES-0001 | C33: =IFERROR(__xludf.DUMMYFUNCTION("""COMPUTED_VALUE"""),"aiftene@ucpa.asso.fr") -> aiftene@ucpa.asso.fr | D33: =IFERROR(__xludf.DUMMYFUNCTION("""COMPUTED_VALUE"""),"https://drive.google.com/file/d/14anGtu9WnFLeXByCFeIk1wPOGn6JT_W9/view?usp=drivesdk") -> https://drive.google.com/file/d/14anGtu9WnFLeXByCFeIk1wPOGn6JT_W9/view?usp=drivesdk
A34: aiftene@ucpa.asso.fr_SES-0002 | B34: =IFERROR(__xludf.DUMMYFUNCTION("""COMPUTED_VALUE"""),"SES-0002") -> SES-0002 | C34: =IFERROR(__xludf.DUMMYFUNCTION("""COMPUTED_VALUE"""),"aiftene@ucpa.asso.fr") -> aiftene@ucpa.asso.fr | D34: =IFERROR(__xludf.DUMMYFUNCTION("""COMPUTED_VALUE"""),"https://drive.google.com/file/d/1uHD5o3n-FD3FnZMLbEXV9Zta0ONXaIQf/view?usp=drivesdk") -> https://drive.google.com/file/d/1uHD5o3n-FD3FnZMLbEXV9Zta0ONXaIQf/view?usp=drivesdk
A35: smoyou@ucpasl.com_SES-0001 | B35: =IFERROR(__xludf.DUMMYFUNCTION("""COMPUTED_VALUE"""),"SES-0001") -> SES-0001 | C35: =IFERROR(__xludf.DUMMYFUNCTION("""COMPUTED_VALUE"""),"smoyou@ucpasl.com") -> smoyou@ucpasl.com | D35: =IFERROR(__xludf.DUMMYFUNCTION("""COMPUTED_VALUE"""),"https://drive.google.com/file/d/1ny4ryAx69_NJtaj_kuP_7ewDOxUOT-xI/view?usp=drivesdk") -> https://drive.google.com/file/d/1ny4ryAx69_NJtaj_kuP_7ewDOxUOT-xI/view?usp=drivesdk
A36: smoyou@ucpasl.com_SES-0002 | B36: =IFERROR(__xludf.DUMMYFUNCTION("""COMPUTED_VALUE"""),"SES-0002") -> SES-0002 | C36: =IFERROR(__xludf.DUMMYFUNCTION("""COMPUTED_VALUE"""),"smoyou@ucpasl.com") -> smoyou@ucpasl.com | D36: =IFERROR(__xludf.DUMMYFUNCTION("""COMPUTED_VALUE"""),"https://drive.google.com/file/d/14oCDy1OWC-mXC63ZFwTDPEiZxUfT6PC2/view?usp=drivesdk") -> https://drive.google.com/file/d/14oCDy1OWC-mXC63ZFwTDPEiZxUfT6PC2/view?usp=drivesdk
A37: sboumrar@vaires-torcy.iledeloisirs.fr_SES-0002 | B37: =IFERROR(__xludf.DUMMYFUNCTION("""COMPUTED_VALUE"""),"SES-0002") -> SES-0002 | C37: =IFERROR(__xludf.DUMMYFUNCTION("""COMPUTED_VALUE"""),"sboumrar@vaires-torcy.iledeloisirs.fr") -> sboumrar@vaires-torcy.iledeloisirs.fr | D37: =IFERROR(__xludf.DUMMYFUNCTION("""COMPUTED_VALUE"""),"https://drive.google.com/file/d/1ozSgNde2Ym21NhsDwG5z2rWHzDgLfnPV/view?usp=drivesdk") -> https://drive.google.com/file/d/1ozSgNde2Ym21NhsDwG5z2rWHzDgLfnPV/view?usp=drivesdk
A38: vcroue@ucpa.asso.fr_SES-0002 | B38: =IFERROR(__xludf.DUMMYFUNCTION("""COMPUTED_VALUE"""),"SES-0002") -> SES-0002 | C38: =IFERROR(__xludf.DUMMYFUNCTION("""COMPUTED_VALUE"""),"vcroue@ucpa.asso.fr") -> vcroue@ucpa.asso.fr | D38: =IFERROR(__xludf.DUMMYFUNCTION("""COMPUTED_VALUE"""),"https://drive.google.com/file/d/1EEgWPTqTPTf5BypxPWiW1RqAX4ZCJsUC/view?usp=drivesdk") -> https://drive.google.com/file/d/1EEgWPTqTPTf5BypxPWiW1RqAX4ZCJsUC/view?usp=drivesdk
A39: benoit_massin@hotmail.com_SES-0001 | B39: =IFERROR(__xludf.DUMMYFUNCTION("""COMPUTED_VALUE"""),"SES-0001") -> SES-0001 | C39: =IFERROR(__xludf.DUMMYFUNCTION("""COMPUTED_VALUE"""),"benoit_massin@hotmail.com") -> benoit_massin@hotmail.com | D39: =IFERROR(__xludf.DUMMYFUNCTION("""COMPUTED_VALUE"""),"https://drive.google.com/file/d/1Px2yc2lA7fQjhlYzEnz8dTRSPijFKlt2/view?usp=drivesdk") -> https://drive.google.com/file/d/1Px2yc2lA7fQjhlYzEnz8dTRSPijFKlt2/view?usp=drivesdk
A40: benoit_massin@hotmail.com_SES-0002 | B40: =IFERROR(__xludf.DUMMYFUNCTION("""COMPUTED_VALUE"""),"SES-0002") -> SES-0002 | C40: =IFERROR(__xludf.DUMMYFUNCTION("""COMPUTED_VALUE"""),"benoit_massin@hotmail.com") -> benoit_massin@hotmail.com | D40: =IFERROR(__xludf.DUMMYFUNCTION("""COMPUTED_VALUE"""),"https://drive.google.com/file/d/1xfX7PF0E29OnQ_ExK6bcNhAUg_vGEOoI/view?usp=drivesdk") -> https://drive.google.com/file/d/1xfX7PF0E29OnQ_ExK6bcNhAUg_vGEOoI/view?usp=drivesdk
...

Sheet SESSION AGENDA
A1: Time | B1: SESSION ID | C1: EVENT ID

Sheet SESSIONS AT
A1: Layout | B1: SESSION | C1: TITRE FORMATION | D1: DATE | E1: HEURE DEBUT | F1: HEURE FIN | G1: LIEU | H1: PLACES RESTANTES | I1: COMPETENCES | J1: LIEN INSCRIPTION | K1: APPLI | L1: LIEN IMAGE APPLI | M1: COULEUR APPLI | N1: DESCRIPTION
A2: CardsContent
B3: =IFERROR(__xludf.DUMMYFUNCTION("QUERY(SESSIONS!B2:AH1002,""SELECT B,O,D,E,F,X,M,P,T,Q,R,S,U WHERE D > DATE '""&TEXT(TODAY(),""yyyy-MM-dd"")&""' AND K = true AND M > 0 order by D "")"),"SES-0002") -> SES-0002 | C3: =IFERROR(__xludf.DUMMYFUNCTION("""COMPUTED_VALUE"""),"Gemini") -> Gemini | D3: =IFERROR(__xludf.DUMMYFUNCTION("""COMPUTED_VALUE"""),46226.0) -> 46226 | E3: =IFERROR(__xludf.DUMMYFUNCTION("""COMPUTED_VALUE"""),0.375) -> 0.375 | F3: =IFERROR(__xludf.DUMMYFUNCTION("""COMPUTED_VALUE"""),0.4791666666678793) -> 0.47916667 | G3: =IFERROR(__xludf.DUMMYFUNCTION("""COMPUTED_VALUE"""),"DISTANCIEL") -> DISTANCIEL | H3: =IFERROR(__xludf.DUMMYFUNCTION("""COMPUTED_VALUE"""),150.0) -> 150 | J3: =IFERROR(__xludf.DUMMYFUNCTION("""COMPUTED_VALUE"""),"https://docs.google.com/forms/d/e/1FAIpQLSeizAy3PO3esDiiugp_bv1E3tocJkuTTplHXzL7ZV9Z6RnVzQ/viewform?usp=pp_url&entry.1709222927=Gemini jeudi 23 juillet 2026 [SES-0002]") -> https://docs.google.com/forms/d/e/1FAIpQLSeizAy3PO3esDiiugp_bv1E3tocJkuTTplHXzL7ZV9Z6RnVzQ/viewform?usp=pp_url&entry.1709222927=Gemini jeudi 23 juillet 2026 [SES-0002] | K3: =IFERROR(__xludf.DUMMYFUNCTION("""COMPUTED_VALUE"""),"GEMINI") -> GEMINI | N3: =IFERROR(__xludf.DUMMYFUNCTION("""COMPUTED_VALUE"""),"Prise en main des outils de Gemini pour savoir l'utilisé de la meilleure façon et d'optimisé c'est taches.") -> Prise en main des outils de Gemini pour savoir l'utilisé de la meilleure façon et d'optimisé c'est taches.
B4: =IFERROR(__xludf.DUMMYFUNCTION("""COMPUTED_VALUE"""),"SES-0003") -> SES-0003 | C4: =IFERROR(__xludf.DUMMYFUNCTION("""COMPUTED_VALUE"""),"Gemini") -> Gemini | D4: =IFERROR(__xludf.DUMMYFUNCTION("""COMPUTED_VALUE"""),46226.0) -> 46226 | E4: =IFERROR(__xludf.DUMMYFUNCTION("""COMPUTED_VALUE"""),0.5833333333321207) -> 0.58333333 | F4: =IFERROR(__xludf.DUMMYFUNCTION("""COMPUTED_VALUE"""),0.6458333333321207) -> 0.64583333 | G4: =IFERROR(__xludf.DUMMYFUNCTION("""COMPUTED_VALUE"""),"DISTANCIEL") -> DISTANCIEL | H4: =IFERROR(__xludf.DUMMYFUNCTION("""COMPUTED_VALUE"""),150.0) -> 150 | J4: =IFERROR(__xludf.DUMMYFUNCTION("""COMPUTED_VALUE"""),"https://docs.google.com/forms/d/e/1FAIpQLSeizAy3PO3esDiiugp_bv1E3tocJkuTTplHXzL7ZV9Z6RnVzQ/viewform?usp=pp_url&entry.1709222927=Gemini jeudi 23 juillet 2026 [SES-0003]") -> https://docs.google.com/forms/d/e/1FAIpQLSeizAy3PO3esDiiugp_bv1E3tocJkuTTplHXzL7ZV9Z6RnVzQ/viewform?usp=pp_url&entry.1709222927=Gemini jeudi 23 juillet 2026 [SES-0003] | K4: =IFERROR(__xludf.DUMMYFUNCTION("""COMPUTED_VALUE"""),"GEMINI") -> GEMINI | N4: =IFERROR(__xludf.DUMMYFUNCTION("""COMPUTED_VALUE"""),"Prise en main des outils de Gemini pour savoir l'utilisé de la meilleure façon et d'optimisé c'est taches.") -> Prise en main des outils de Gemini pour savoir l'utilisé de la meilleure façon et d'optimisé c'est taches.

Sheet FEUILLE DE PRESENCE
C3: Google Slides niveau 2 | le vendredi 6 novembre 2020 de 11:15 à 12:15 | DISTANCIEL [SES-0018]
D4: =IFERROR(__xludf.DUMMYFUNCTION("IF(C3<>"""", IFNA(REGEXREPLACE(REGEXEXTRACT(C3,""\[.*\]""),""\[|\]"","""")),)"),"SES-0018") -> SES-0018
B6: =IFNA(VLOOKUP(D4,SESSIONS!B:D,3,FALSE),"") | D6: =IFNA(VLOOKUP(D4,SESSIONS!B:E,4,FALSE),"") | E6: =IFNA(VLOOKUP(D4,SESSIONS!B:F,5,FALSE),"")
B8: Civilité | C8: Prénom | D8: NOM
B9: =IFERROR(__xludf.DUMMYFUNCTION("QUERY('INSCRIPTIONS OLD'!A:L,""SELECT G,H,I WHERE A='""&D4&""' ORDER BY F,E"",0)"),"#N/A") -> #N/A

Sheet LIEUX
A1: N | B1: {=IF(C:C<>"",IF(C:C=C1,"Lieu id","LIEU-"&TEXT(A:A,"000")),)} -> Lieu id | C1: NOM | D1: ADRESSE | E1: CP | F1: VILLE | G1: ACCES | H1: LIEN MAP | I1: {=IF(B:B<>"",C:C&" ["&B:B&"]",)} -> NOM [Lieu id] | J1: {=IF(B:B<>"",C:C&IF(F:F<>""," ("&F:F&")",),)} -> NOM (VILLE)
A2: 1 | B2: LIEU-001 | C2: DISTANCIEL | D2: https://meet.google.com/apv-qoem-zpc | G2: Pour vous connecter, utilisez le lien suivant : https://meet.google.com/apv-qoem-zpc | I2: DISTANCIEL [LIEU-001] | J2: DISTANCIEL
A3: 2
A4: 3
A5: 4
A6: 5
A7: 6
A8: 7
A9: 8
A10: 9
A11: 10
A12: 11
A13: 12
A14: 13
... A34: 33

Sheet IMPORT TLA
A1: =IFERROR(__xludf.DUMMYFUNCTION("IMPORTRANGE(PARAMETRES!C27,""TLA_ID"")"),"#N/A") -> #N/A | B1: =IFERROR(__xludf.DUMMYFUNCTION("IMPORTRANGE(PARAMETRES!C27,""TLA_SESSION_PARTICIPANTS"")"),"#N/A") -> #N/A

Sheet IMPORT FORMATEURS
A1: =IFERROR(__xludf.DUMMYFUNCTION("IMPORTRANGE(""https://docs.google.com/spreadsheets/d/1A_q8zXIhOo9mCubJL0Vq4O9abvtvW53qPvNmquKHmcE/"",""COACH_ID"")"),"cid") -> cid | B1: =IFERROR(__xludf.DUMMYFUNCTION("IMPORTRANGE(""https://docs.google.com/spreadsheets/d/1A_q8zXIhOo9mCubJL0Vq4O9abvtvW53qPvNmquKHmcE/"",""COACH_EMAIL"")"),"email") -> email | C1: =IFERROR(__xludf.DUMMYFUNCTION("IMPORTRANGE(""https://docs.google.com/spreadsheets/d/1A_q8zXIhOo9mCubJL0Vq4O9abvtvW53qPvNmquKHmcE/"",""COACH_NOM"")"),"lastName") -> lastName | D1: =IFERROR(__xludf.DUMMYFUNCTION("IMPORTRANGE(""https://docs.google.com/spreadsheets/d/1A_q8zXIhOo9mCubJL0Vq4O9abvtvW53qPvNmquKHmcE/"",""COACH_PRENOM"")"),"firstName") -> firstName | E1: selection | G1: =IFERROR(__xludf.DUMMYFUNCTION("query(A:E,""SELECT A,B,C,D WHERE E = true"") "),"cid") -> cid | H1: =IFERROR(__xludf.DUMMYFUNCTION("""COMPUTED_VALUE"""),"email") -> email | I1: =IFERROR(__xludf.DUMMYFUNCTION("""COMPUTED_VALUE"""),"lastName") -> lastName | J1: =IFERROR(__xludf.DUMMYFUNCTION("""COMPUTED_VALUE"""),"firstName") -> firstName | K1: {=IF(G:G<>"",J:J&" "&I:I&" ["&text(G:G,"000")&"]",)} -> firstName lastName [cid]
E2: FALSE | G2: =IFERROR(__xludf.DUMMYFUNCTION("""COMPUTED_VALUE"""),11.0) -> 11 | H2: =IFERROR(__xludf.DUMMYFUNCTION("""COMPUTED_VALUE"""),"christophe.serio@sro-coach.fr") -> christophe.serio@sro-coach.fr | I2: =IFERROR(__xludf.DUMMYFUNCTION("""COMPUTED_VALUE"""),"SERIO") -> SERIO | J2: =IFERROR(__xludf.DUMMYFUNCTION("""COMPUTED_VALUE"""),"Christophe") -> Christophe | K2: Christophe SERIO [011]
A3: =IFERROR(__xludf.DUMMYFUNCTION("""COMPUTED_VALUE"""),42.0) -> 42 | C3: =IFERROR(__xludf.DUMMYFUNCTION("""COMPUTED_VALUE"""),"ADMIN") -> ADMIN | D3: =IFERROR(__xludf.DUMMYFUNCTION("""COMPUTED_VALUE"""),"Super") -> Super | E3: FALSE | G3: =IFERROR(__xludf.DUMMYFUNCTION("""COMPUTED_VALUE"""),1.0) -> 1 | H3: =IFERROR(__xludf.DUMMYFUNCTION("""COMPUTED_VALUE"""),"thierry@numericoach.fr") -> thierry@numericoach.fr | I3: =IFERROR(__xludf.DUMMYFUNCTION("""COMPUTED_VALUE"""),"VANOFFE") -> VANOFFE | J3: =IFERROR(__xludf.DUMMYFUNCTION("""COMPUTED_VALUE"""),"Thierry") -> Thierry | K3: Thierry VANOFFE [001]
A4: =IFERROR(__xludf.DUMMYFUNCTION("""COMPUTED_VALUE"""),52.0) -> 52 | B4: =IFERROR(__xludf.DUMMYFUNCTION("""COMPUTED_VALUE"""),"mohamed.m.bahri@gmail.com") -> mohamed.m.bahri@gmail.com | C4: =IFERROR(__xludf.DUMMYFUNCTION("""COMPUTED_VALUE"""),"BAHRI") -> BAHRI | D4: =IFERROR(__xludf.DUMMYFUNCTION("""COMPUTED_VALUE"""),"Mohamed") -> Mohamed | E4: FALSE
A5: =IFERROR(__xludf.DUMMYFUNCTION("""COMPUTED_VALUE"""),16.0) -> 16 | B5: =IFERROR(__xludf.DUMMYFUNCTION("""COMPUTED_VALUE"""),"philippe.behier@acef-france.fr") -> philippe.behier@acef-france.fr | C5: =IFERROR(__xludf.DUMMYFUNCTION("""COMPUTED_VALUE"""),"BEHIER") -> BEHIER | D5: =IFERROR(__xludf.DUMMYFUNCTION("""COMPUTED_VALUE"""),"Philippe") -> Philippe | E5: FALSE
A6: =IFERROR(__xludf.DUMMYFUNCTION("""COMPUTED_VALUE"""),7.0) -> 7 | B6: =IFERROR(__xludf.DUMMYFUNCTION("""COMPUTED_VALUE"""),"dev@numericoach.fr") -> dev@numericoach.fr | C6: =IFERROR(__xludf.DUMMYFUNCTION("""COMPUTED_VALUE"""),"BELOHLAVEK") -> BELOHLAVEK | D6: =IFERROR(__xludf.DUMMYFUNCTION("""COMPUTED_VALUE"""),"Boris") -> Boris | E6: FALSE
A7: =IFERROR(__xludf.DUMMYFUNCTION("""COMPUTED_VALUE"""),17.0) -> 17 | B7: =IFERROR(__xludf.DUMMYFUNCTION("""COMPUTED_VALUE"""),"fabrice@epidosi.fr") -> fabrice@epidosi.fr | C7: =IFERROR(__xludf.DUMMYFUNCTION("""COMPUTED_VALUE"""),"BOLLI") -> BOLLI | D7: =IFERROR(__xludf.DUMMYFUNCTION("""COMPUTED_VALUE"""),"Fabrice") -> Fabrice | E7: FALSE
A8: =IFERROR(__xludf.DUMMYFUNCTION("""COMPUTED_VALUE"""),37.0) -> 37 | B8: =IFERROR(__xludf.DUMMYFUNCTION("""COMPUTED_VALUE"""),"benjamin@benjamin-caron.fr") -> benjamin@benjamin-caron.fr | C8: =IFERROR(__xludf.DUMMYFUNCTION("""COMPUTED_VALUE"""),"CARON") -> CARON | D8: =IFERROR(__xludf.DUMMYFUNCTION("""COMPUTED_VALUE"""),"Benjamin") -> Benjamin | E8: FALSE
A9: =IFERROR(__xludf.DUMMYFUNCTION("""COMPUTED_VALUE"""),10.0) -> 10 | B9: =IFERROR(__xludf.DUMMYFUNCTION("""COMPUTED_VALUE"""),"cyrille.carteret@fastlearner.fr") -> cyrille.carteret@fastlearner.fr | C9: =IFERROR(__xludf.DUMMYFUNCTION("""COMPUTED_VALUE"""),"CARTERET") -> CARTERET | D9: =IFERROR(__xludf.DUMMYFUNCTION("""COMPUTED_VALUE"""),"Cyrille") -> Cyrille | E9: FALSE
A10: =IFERROR(__xludf.DUMMYFUNCTION("""COMPUTED_VALUE"""),45.0) -> 45 | B10: =IFERROR(__xludf.DUMMYFUNCTION("""COMPUTED_VALUE"""),"nathan.cohen@hatofa.com") -> nathan.cohen@hatofa.com | C10: =IFERROR(__xludf.DUMMYFUNCTION("""COMPUTED_VALUE"""),"COHEN") -> COHEN | D10: =IFERROR(__xludf.DUMMYFUNCTION("""COMPUTED_VALUE"""),"Nathan") -> Nathan | E10: FALSE
A11: =IFERROR(__xludf.DUMMYFUNCTION("""COMPUTED_VALUE"""),18.0) -> 18 | B11: =IFERROR(__xludf.DUMMYFUNCTION("""COMPUTED_VALUE"""),"thomascolombet0@gmail.com") -> thomascolombet0@gmail.com | C11: =IFERROR(__xludf.DUMMYFUNCTION("""COMPUTED_VALUE"""),"COLOMBET") -> COLOMBET | D11: =IFERROR(__xludf.DUMMYFUNCTION("""COMPUTED_VALUE"""),"Thomas") -> Thomas | E11: FALSE
A12: =IFERROR(__xludf.DUMMYFUNCTION("""COMPUTED_VALUE"""),4.0) -> 4 | B12: =IFERROR(__xludf.DUMMYFUNCTION("""COMPUTED_VALUE"""),"jmd@talandria.fr") -> jmd@talandria.fr | C12: =IFERROR(__xludf.DUMMYFUNCTION("""COMPUTED_VALUE"""),"D'ANDRIA") -> D'ANDRIA | D12: =IFERROR(__xludf.DUMMYFUNCTION("""COMPUTED_VALUE"""),"Jean-Marc") -> Jean-Marc | E12: FALSE
A13: =IFERROR(__xludf.DUMMYFUNCTION("""COMPUTED_VALUE"""),48.0) -> 48 | B13: =IFERROR(__xludf.DUMMYFUNCTION("""COMPUTED_VALUE"""),"josephdandria@digitalchangeconsulting.com") -> josephdandria@digitalchangeconsulting.com | C13: =IFERROR(__xludf.DUMMYFUNCTION("""COMPUTED_VALUE"""),"D'ANDRIA") -> D'ANDRIA | D13: =IFERROR(__xludf.DUMMYFUNCTION("""COMPUTED_VALUE"""),"Joseph") -> Joseph | E13: FALSE
A14: =IFERROR(__xludf.DUMMYFUNCTION("""COMPUTED_VALUE"""),39.0) -> 39 | B14: =IFERROR(__xludf.DUMMYFUNCTION("""COMPUTED_VALUE"""),"leastpierre@lookandream.com") -> leastpierre@lookandream.com | C14: =IFERROR(__xludf.DUMMYFUNCTION("""COMPUTED_VALUE"""),"DEBORDE") -> DEBORDE | D14: =IFERROR(__xludf.DUMMYFUNCTION("""COMPUTED_VALUE"""),"Léa") -> Léa | E14: FALSE
A15: =IFERROR(__xludf.DUMMYFUNCTION("""COMPUTED_VALUE"""),23.0) -> 23 | B15: =IFERROR(__xludf.DUMMYFUNCTION("""COMPUTED_VALUE"""),"debreil.remi@gmail.com") -> debreil.remi@gmail.com | C15: =IFERROR(__xludf.DUMMYFUNCTION("""COMPUTED_VALUE"""),"DEBREIL") -> DEBREIL | D15: =IFERROR(__xludf.DUMMYFUNCTION("""COMPUTED_VALUE"""),"Rémi") -> Rémi | E15: FALSE
A16: =IFERROR(__xludf.DUMMYFUNCTION("""COMPUTED_VALUE"""),22.0) -> 22 | B16: =IFERROR(__xludf.DUMMYFUNCTION("""COMPUTED_VALUE"""),"fdesaunois@gapps-attitude.com") -> fdesaunois@gapps-attitude.com | C16: =IFERROR(__xludf.DUMMYFUNCTION("""COMPUTED_VALUE"""),"DESAUNOIS") -> DESAUNOIS | D16: =IFERROR(__xludf.DUMMYFUNCTION("""COMPUTED_VALUE"""),"Frédéric") -> Frédéric | E16: FALSE
A17: =IFERROR(__xludf.DUMMYFUNCTION("""COMPUTED_VALUE"""),46.0) -> 46 | B17: =IFERROR(__xludf.DUMMYFUNCTION("""COMPUTED_VALUE"""),"fabrice.escalant@pme.digital") -> fabrice.escalant@pme.digital | C17: =IFERROR(__xludf.DUMMYFUNCTION("""COMPUTED_VALUE"""),"ESCALANT") -> ESCALANT | D17: =IFERROR(__xludf.DUMMYFUNCTION("""COMPUTED_VALUE"""),"Fabrice") -> Fabrice | E17: FALSE
A18: =IFERROR(__xludf.DUMMYFUNCTION("""COMPUTED_VALUE"""),25.0) -> 25 | B18: =IFERROR(__xludf.DUMMYFUNCTION("""COMPUTED_VALUE"""),"arthur.gentric.ext@numericoach.fr") -> arthur.gentric.ext@numericoach.fr | C18: =IFERROR(__xludf.DUMMYFUNCTION("""COMPUTED_VALUE"""),"GENTRIC") -> GENTRIC | D18: =IFERROR(__xludf.DUMMYFUNCTION("""COMPUTED_VALUE"""),"Arthur") -> Arthur | E18: FALSE
A19: =IFERROR(__xludf.DUMMYFUNCTION("""COMPUTED_VALUE"""),38.0) -> 38 | B19: =IFERROR(__xludf.DUMMYFUNCTION("""COMPUTED_VALUE"""),"florent.gestin@onesession.fr") -> florent.gestin@onesession.fr | C19: =IFERROR(__xludf.DUMMYFUNCTION("""COMPUTED_VALUE"""),"GESTIN") -> GESTIN | D19: =IFERROR(__xludf.DUMMYFUNCTION("""COMPUTED_VALUE"""),"Florent") -> Florent | E19: FALSE
A20: =IFERROR(__xludf.DUMMYFUNCTION("""COMPUTED_VALUE"""),43.0) -> 43 | B20: =IFERROR(__xludf.DUMMYFUNCTION("""COMPUTED_VALUE"""),"stephanie.girodet.ext@numericoach.fr") -> stephanie.girodet.ext@numericoach.fr | C20: =IFERROR(__xludf.DUMMYFUNCTION("""COMPUTED_VALUE"""),"GIRODET") -> GIRODET | D20: =IFERROR(__xludf.DUMMYFUNCTION("""COMPUTED_VALUE"""),"Stéphanie") -> Stéphanie | E20: FALSE
A21: =IFERROR(__xludf.DUMMYFUNCTION("""COMPUTED_VALUE"""),49.0) -> 49 | B21: =IFERROR(__xludf.DUMMYFUNCTION("""COMPUTED_VALUE"""),"philippe@numeric-transition.fr") -> philippe@numeric-transition.fr | C21: =IFERROR(__xludf.DUMMYFUNCTION("""COMPUTED_VALUE"""),"GUERIN") -> GUERIN | D21: =IFERROR(__xludf.DUMMYFUNCTION("""COMPUTED_VALUE"""),"Philippe") -> Philippe | E21: FALSE
A22: =IFERROR(__xludf.DUMMYFUNCTION("""COMPUTED_VALUE"""),13.0) -> 13 | B22: =IFERROR(__xludf.DUMMYFUNCTION("""COMPUTED_VALUE"""),"emberylguibourt@gmail.com") -> emberylguibourt@gmail.com | C22: =IFERROR(__xludf.DUMMYFUNCTION("""COMPUTED_VALUE"""),"GUIBOURT") -> GUIBOURT | D22: =IFERROR(__xludf.DUMMYFUNCTION("""COMPUTED_VALUE"""),"Béryl") -> Béryl | E22: FALSE
A23: =IFERROR(__xludf.DUMMYFUNCTION("""COMPUTED_VALUE"""),20.0) -> 20 | B23: =IFERROR(__xludf.DUMMYFUNCTION("""COMPUTED_VALUE"""),"sguillerand@gmail.com") -> sguillerand@gmail.com | C23: =IFERROR(__xludf.DUMMYFUNCTION("""COMPUTED_VALUE"""),"GUILLERAND") -> GUILLERAND | D23: =IFERROR(__xludf.DUMMYFUNCTION("""COMPUTED_VALUE"""),"Stéphane") -> Stéphane | E23: FALSE
A24: =IFERROR(__xludf.DUMMYFUNCTION("""COMPUTED_VALUE"""),40.0) -> 40 | B24: =IFERROR(__xludf.DUMMYFUNCTION("""COMPUTED_VALUE"""),"hammouti.redoane@gmail.com") -> hammouti.redoane@gmail.com | C24: =IFERROR(__xludf.DUMMYFUNCTION("""COMPUTED_VALUE"""),"HAMMOUTI") -> HAMMOUTI | D24: =IFERROR(__xludf.DUMMYFUNCTION("""COMPUTED_VALUE"""),"Redoane") -> Redoane | E24: FALSE
A25: =IFERROR(__xludf.DUMMYFUNCTION("""COMPUTED_VALUE"""),24.0) -> 24 | B25: =IFERROR(__xludf.DUMMYFUNCTION("""COMPUTED_VALUE"""),"gform@gregoryhennebel.fr") -> gform@gregoryhennebel.fr | C25: =IFERROR(__xludf.DUMMYFUNCTION("""COMPUTED_VALUE"""),"HENNEBEL") -> HENNEBEL | D25: =IFERROR(__xludf.DUMMYFUNCTION("""COMPUTED_VALUE"""),"Grégory") -> Grégory | E25: FALSE
A26: =IFERROR(__xludf.DUMMYFUNCTION("""COMPUTED_VALUE"""),26.0) -> 26 | B26: =IFERROR(__xludf.DUMMYFUNCTION("""COMPUTED_VALUE"""),"office@numericoach.fr contact@kapandco.fr") -> office@numericoach.fr contact@kapandco.fr | C26: =IFERROR(__xludf.DUMMYFUNCTION("""COMPUTED_VALUE"""),"INGELS") -> INGELS | D26: =IFERROR(__xludf.DUMMYFUNCTION("""COMPUTED_VALUE"""),"Christelle") -> Christelle | E26: FALSE
A27: =IFERROR(__xludf.DUMMYFUNCTION("""COMPUTED_VALUE"""),15.0) -> 15 | B27: =IFERROR(__xludf.DUMMYFUNCTION("""COMPUTED_VALUE"""),"jean-paul.jourdan@gmail.com") -> jean-paul.jourdan@gmail.com | C27: =IFERROR(__xludf.DUMMYFUNCTION("""COMPUTED_VALUE"""),"JOURDAN") -> JOURDAN | D27: =IFERROR(__xludf.DUMMYFUNCTION("""COMPUTED_VALUE"""),"Jean-Paul") -> Jean-Paul | E27: FALSE
A28: =IFERROR(__xludf.DUMMYFUNCTION("""COMPUTED_VALUE"""),6.0) -> 6 | B28: =IFERROR(__xludf.DUMMYFUNCTION("""COMPUTED_VALUE"""),"aleksander@leboudoir-studio.com") -> aleksander@leboudoir-studio.com | C28: =IFERROR(__xludf.DUMMYFUNCTION("""COMPUTED_VALUE"""),"KAUFMANN") -> KAUFMANN | D28: =IFERROR(__xludf.DUMMYFUNCTION("""COMPUTED_VALUE"""),"Aleksander") -> Aleksander | E28: FALSE
A29: =IFERROR(__xludf.DUMMYFUNCTION("""COMPUTED_VALUE"""),19.0) -> 19 | B29: =IFERROR(__xludf.DUMMYFUNCTION("""COMPUTED_VALUE"""),"christof.lefeuvre@clicc.fr") -> christof.lefeuvre@clicc.fr | C29: =IFERROR(__xludf.DUMMYFUNCTION("""COMPUTED_VALUE"""),"LEFEUVRE") -> LEFEUVRE | D29: =IFERROR(__xludf.DUMMYFUNCTION("""COMPUTED_VALUE"""),"Christof") -> Christof | E29: FALSE
A30: =IFERROR(__xludf.DUMMYFUNCTION("""COMPUTED_VALUE"""),30.0) -> 30 | B30: =IFERROR(__xludf.DUMMYFUNCTION("""COMPUTED_VALUE"""),"laurene.lefevre95@gmail.com") -> laurene.lefevre95@gmail.com | C30: =IFERROR(__xludf.DUMMYFUNCTION("""COMPUTED_VALUE"""),"LEFEVRE") -> LEFEVRE | D30: =IFERROR(__xludf.DUMMYFUNCTION("""COMPUTED_VALUE"""),"Laurène") -> Laurène | E30: FALSE
A31: =IFERROR(__xludf.DUMMYFUNCTION("""COMPUTED_VALUE"""),27.0) -> 27 | B31: =IFERROR(__xludf.DUMMYFUNCTION("""COMPUTED_VALUE"""),"formateur@lesagedavid.fr") -> formateur@lesagedavid.fr | C31: =IFERROR(__xludf.DUMMYFUNCTION("""COMPUTED_VALUE"""),"LESAGE") -> LESAGE | D31: =IFERROR(__xludf.DUMMYFUNCTION("""COMPUTED_VALUE"""),"David") -> David | E31: FALSE
A32: =IFERROR(__xludf.DUMMYFUNCTION("""COMPUTED_VALUE"""),47.0) -> 47 | B32: =IFERROR(__xludf.DUMMYFUNCTION("""COMPUTED_VALUE"""),"leve.nicolas@gmail.com") -> leve.nicolas@gmail.com | C32: =IFERROR(__xludf.DUMMYFUNCTION("""COMPUTED_VALUE"""),"LEVE") -> LEVE | D32: =IFERROR(__xludf.DUMMYFUNCTION("""COMPUTED_VALUE"""),"Nicolas") -> Nicolas | E32: FALSE
A33: =IFERROR(__xludf.DUMMYFUNCTION("""COMPUTED_VALUE"""),9.0) -> 9 | B33: =IFERROR(__xludf.DUMMYFUNCTION("""COMPUTED_VALUE"""),"olivier.loncin@jalons.be") -> olivier.loncin@jalons.be | C33: =IFERROR(__xludf.DUMMYFUNCTION("""COMPUTED_VALUE"""),"LONCIN") -> LONCIN | D33: =IFERROR(__xludf.DUMMYFUNCTION("""COMPUTED_VALUE"""),"Olivier") -> Olivier | E33: FALSE
A34: =IFERROR(__xludf.DUMMYFUNCTION("""COMPUTED_VALUE"""),33.0) -> 33 | B34: =IFERROR(__xludf.DUMMYFUNCTION("""COMPUTED_VALUE"""),"sandrine@cogitus-conseil.fr") -> sandrine@cogitus-conseil.fr | C34: =IFERROR(__xludf.DUMMYFUNCTION("""COMPUTED_VALUE"""),"MARQUIS") -> MARQUIS | D34: =IFERROR(__xludf.DUMMYFUNCTION("""COMPUTED_VALUE"""),"Sandrine") -> Sandrine | E34: FALSE
A35: =IFERROR(__xludf.DUMMYFUNCTION("""COMPUTED_VALUE"""),21.0) -> 21 | B35: =IFERROR(__xludf.DUMMYFUNCTION("""COMPUTED_VALUE"""),"antoine.martin@amcms.net") -> antoine.martin@amcms.net | C35: =IFERROR(__xludf.DUMMYFUNCTION("""COMPUTED_VALUE"""),"MARTIN") -> MARTIN | D35: =IFERROR(__xludf.DUMMYFUNCTION("""COMPUTED_VALUE"""),"Antoine") -> Antoine | E35: FALSE
A36: =IFERROR(__xludf.DUMMYFUNCTION("""COMPUTED_VALUE"""),29.0) -> 29 | B36: =IFERROR(__xludf.DUMMYFUNCTION("""COMPUTED_VALUE"""),"mazonier@gmail.com") -> mazonier@gmail.com | C36: =IFERROR(__xludf.DUMMYFUNCTION("""COMPUTED_VALUE"""),"MAZONIER") -> MAZONIER | D36: =IFERROR(__xludf.DUMMYFUNCTION("""COMPUTED_VALUE"""),"Jean-Pascal") -> Jean-Pascal | E36: FALSE
A37: =IFERROR(__xludf.DUMMYFUNCTION("""COMPUTED_VALUE"""),32.0) -> 32 | B37: =IFERROR(__xludf.DUMMYFUNCTION("""COMPUTED_VALUE"""),"jstephane.michalak@gmail.com") -> jstephane.michalak@gmail.com | C37: =IFERROR(__xludf.DUMMYFUNCTION("""COMPUTED_VALUE"""),"MICHALAK") -> MICHALAK | D37: =IFERROR(__xludf.DUMMYFUNCTION("""COMPUTED_VALUE"""),"Jean-Stephane") -> Jean-Stephane | E37: FALSE
A38: =IFERROR(__xludf.DUMMYFUNCTION("""COMPUTED_VALUE"""),35.0) -> 35 | C38: =IFERROR(__xludf.DUMMYFUNCTION("""COMPUTED_VALUE"""),"MITAULT") -> MITAULT | D38: =IFERROR(__xludf.DUMMYFUNCTION("""COMPUTED_VALUE"""),"Jean") -> Jean | E38: FALSE
A39: =IFERROR(__xludf.DUMMYFUNCTION("""COMPUTED_VALUE"""),3.0) -> 3 | B39: =IFERROR(__xludf.DUMMYFUNCTION("""COMPUTED_VALUE"""),"isabelle@isabellenarboni.com") -> isabelle@isabellenarboni.com | C39: =IFERROR(__xludf.DUMMYFUNCTION("""COMPUTED_VALUE"""),"NARBONI") -> NARBONI | D39: =IFERROR(__xludf.DUMMYFUNCTION("""COMPUTED_VALUE"""),"Isabelle") -> Isabelle | E39: FALSE
A40: =IFERROR(__xludf.DUMMYFUNCTION("""COMPUTED_VALUE"""),12.0) -> 12 | B40: =IFERROR(__xludf.DUMMYFUNCTION("""COMPUTED_VALUE"""),"alternatives13@gmail.com") -> alternatives13@gmail.com | C40: =IFERROR(__xludf.DUMMYFUNCTION("""COMPUTED_VALUE"""),"PICANO SALAZAR") -> PICANO SALAZAR | D40: =IFERROR(__xludf.DUMMYFUNCTION("""COMPUTED_VALUE"""),"Véronique") -> Véronique | E40: FALSE
...

Sheet VALIDATION
A1: OK

Sheet CHARGES DE FORMATION
A1: EMAIL CG | B1: POSTE | C1: TEL | D1: PRENOM | E1: NOM | F1: {=IF(D:D<>"",D:D&" "&E:E,)} -> PRENOM NOM

Sheet ENTITES
A1: ID | B1: {=IF(C:C<>"",IF(C:C=C1,"DENOMINATION",C:C&IF(D:D<>""," / "&D:D,)&" ["&A:A&"]"),)} -> DENOMINATION | C1: NOM | D1: MARQUE | E1: RF 1 | F1: RF 2 | G1: LIEN LOGO | H1: ADRESSE | I1: ADRESSE SUITE | J1: CP | K1: VILLE | L1: =IFERROR(__xludf.DUMMYFUNCTION("ArrayFormula(IF(G:G<>"""",REGEXEXTRACT(G:G,""[a-zA-z0-9-]{33}""),))"),"#N/A") -> #N/A
A2: 1 | B2: Entité 1 / Sous Entité [1] | C2: Entité 1 | D2: Sous Entité
A3: 2
A4: 3
A5: 4
